<?xml version="1.0"?>
<robot name="r2d2">
  <link name="base_link">
    <visual>
      <geometry>
        <box size="0.40357 0.272 0.19334"/>
      </geometry>
      <material name="Red"><color rgba="1 0 0 1"/></material>
      <origin rpy="0 0 0" xyz="0 0 0.18057  "/>
    </visual>
  </link>
<!-- front right wheel -->
  <link name="front_right_axle">
    <visual>
      <geometry>
        <cylinder length="0.060" radius="0.025"/>
      </geometry>
      <material name="Black"><color rgba="0 0 0 1"/></material>
      <origin rpy="1.57075 0 0" xyz="0 0 0"/>
    </visual>
  </link>

  <link name="front_right_wheel">
    <visual>
      <geometry>
        <cylinder length="0.09525" radius="0.111125"/>
      </geometry>
      <material name="Black"><color rgba="0 0 0 1"/></material>
      <origin rpy="1.57075 0 0" xyz="0 0 0"/>
    </visual>
  </link>

  <joint name="base_front_right_axle_joint" type="fixed">
    <parent link="base_link"/>
    <child link="front_right_axle"/>
    <origin xyz="0.135 -0.156 0.111"/>
  </joint>

  <joint name="front_right_wheel_joint" type="continuous">
    <axis rpy="0 0 0" xyz="0 1 0"/>
    <parent link="front_right_axle"/>
    <child link="front_right_wheel"/>
    <origin xyz="0 -0.041 0"/>
  </joint>

<!-- back right wheel -->
  <link name="back_right_axle">
    <visual>
      <geometry>
        <cylinder length="0.060" radius="0.025"/>
      </geometry>
      <material name="Black"><color rgba="0 0 0 1"/></material>
      <origin rpy="1.57075 0 0" xyz="0 0 0"/>
    </visual>
  </link>

  <link name="back_right_wheel">
    <visual>
      <geometry>
        <cylinder length="0.09525" radius="0.111125"/>
      </geometry>
      <material name="Black"><color rgba="0 0 0 1"/></material>
      <origin rpy="1.57075 0 0" xyz="0 0 0"/>
    </visual>
  </link>

  <joint name="base_back_right_axle_joint" type="fixed">
    <parent link="base_link"/>
    <child link="back_right_axle"/>
    <origin xyz="-0.134 -0.156 0.111"/>
  </joint>

  <joint name="back_right_wheel_joint" type="continuous">
    <axis rpy="0 0 0" xyz="0 1 0"/>
    <parent link="back_right_axle"/>
    <child link="back_right_wheel"/>
    <origin xyz="0 -0.041 0"/>
  </joint>

<!-- front left wheel -->
  <link name="front_left_axle">
    <visual>
      <geometry>
        <cylinder length="0.060" radius="0.025"/>
      </geometry>
      <material name="Black"><color rgba="0 0 0 1"/></material>
      <origin rpy="1.57075 0 0" xyz="0 0 0"/>
    </visual>
  </link>

  <link name="front_left_wheel">
    <visual>
      <geometry>
        <cylinder length="0.09525" radius="0.111125"/>
      </geometry>
      <material name="Black"><color rgba="0 0 0 1"/></material>
      <origin rpy="1.57075 0 0" xyz="0 0 0"/>
    </visual>
  </link>

  <joint name="base_front_left_axle_joint" type="fixed">
    <parent link="base_link"/>
    <child link="front_left_axle"/>
    <origin xyz="0.135 0.156 0.111"/>
  </joint>

  <joint name="front_left_wheel_joint" type="continuous">
    <axis rpy="0 0 0" xyz="0 1 0"/>
    <parent link="front_left_axle"/>
    <child link="front_left_wheel"/>
    <origin xyz="0 0.041 0"/>
  </joint>

<!-- back left wheel -->
  <link name="back_left_axle">
    <visual>
      <geometry>
        <cylinder length="0.060" radius="0.025"/>
      </geometry>
      <material name="Black"><color rgba="0 0 0 1"/></material>
      <origin rpy="1.57075 0 0" xyz="0 0 0"/>
    </visual>
  </link>

  <link name="back_left_wheel">
    <visual>
      <geometry>
        <cylinder length="0.09525" radius="0.111125"/>
      </geometry>
      <material name="Black"><color rgba="0 0 0 1"/></material>
      <origin rpy="1.57075 0 0" xyz="0 0 0"/>
    </visual>
  </link>

  <joint name="base_back_left_axle_joint" type="fixed">
    <parent link="base_link"/>
    <child link="back_left_axle"/>
    <origin xyz="-0.134 0.156 0.111"/>
  </joint>

  <joint name="back_left_wheel_joint" type="continuous">
    <axis rpy="0 0 0" xyz="0 1 0"/>
    <parent link="back_left_axle"/>
    <child link="back_left_wheel"/>
    <origin xyz="0 0.041 0"/>
  </joint>

<!-- kinect -->
  <link name="camera_link">
    <visual>
      <geometry>
        <box size="0.06 0.28 0.04"/>
      </geometry>
      <material name="Black"><color rgba="0 0 0 1"/></material>
      <origin rpy="0 0 0" xyz="0 0 0"/>
    </visual>
  </link>

  <joint name="base_to_camera" type="fixed">
    <parent link="base_link"/>
    <child link="camera_link"/>
    <origin xyz="-0.134 0 0.57724"/>
  </joint>

<!-- left aluminium extrusion -->
  <link name="left_aluminium_extrusion">
    <visual>
      <geometry>
        <box size="0.03 0.03 0.28"/>
      </geometry>
      <material name="Grey"><color rgba="0.5 0.5 0.5 1"/></material>
      <origin rpy="0 0 0" xyz="0 0 0"/>
    </visual>
  </link>

  <joint name="base_to_left_alu" type="fixed">
    <parent link="base_link"/>
    <child link="left_aluminium_extrusion"/>
    <origin xyz="-0.134 0.07 0.41724"/>
  </joint>

<!-- right aluminium extrusion -->
  <link name="right_aluminium_extrusion">
    <visual>
      <geometry>
        <box size="0.03 0.03 0.28"/>
      </geometry>
      <material name="Grey"><color rgba="0.5 0.5 0.5 1"/></material>
      <origin rpy="0 0 0" xyz="0 0 0"/>
    </visual>
  </link>

  <joint name="base_to_right_alu" type="fixed">
    <parent link="base_link"/>
    <child link="right_aluminium_extrusion"/>
    <origin xyz="-0.134 -0.07 0.41724"/>
  </joint>

</robot>